[2024-10-21T20:54:24.255+0700] {local_task_job_runner.py:123} INFO - ::group::Pre task execution logs
[2024-10-21T20:54:24.271+0700] {taskinstance.py:2612} INFO - Dependencies all met for dep_context=non-requeueable deps ti=<TaskInstance: bash_example.test_task manual__2024-10-21T13:52:38.529305+00:00 [queued]>
[2024-10-21T20:54:24.279+0700] {taskinstance.py:2612} INFO - Dependencies all met for dep_context=requeueable deps ti=<TaskInstance: bash_example.test_task manual__2024-10-21T13:52:38.529305+00:00 [queued]>
[2024-10-21T20:54:24.280+0700] {taskinstance.py:2865} INFO - Starting attempt 1 of 2
[2024-10-21T20:54:24.294+0700] {taskinstance.py:2888} INFO - Executing <Task(BashOperator): test_task> on 2024-10-21 13:52:38.529305+00:00
[2024-10-21T20:54:24.301+0700] {standard_task_runner.py:72} INFO - Started process 5887 to run task
[2024-10-21T20:54:24.310+0700] {standard_task_runner.py:104} INFO - Running: ['airflow', 'tasks', 'run', 'bash_example', 'test_task', 'manual__2024-10-21T13:52:38.529305+00:00', '--job-id', '18', '--raw', '--subdir', 'DAGS_FOLDER/example_dag.py', '--cfg-path', '/var/folders/3z/w6kw66r93jxd4b5xvgpxfbkm0000gn/T/tmpm7yv4xra']
[2024-10-21T20:54:24.312+0700] {standard_task_runner.py:105} INFO - Job 18: Subtask test_task
[2024-10-21T20:54:24.368+0700] {task_command.py:467} INFO - Running <TaskInstance: bash_example.test_task manual__2024-10-21T13:52:38.529305+00:00 [running]> on host macbook-pro-khxng-krissanapong.local
[2024-10-21T20:54:24.449+0700] {taskinstance.py:3131} INFO - Exporting env vars: AIRFLOW_CTX_DAG_EMAIL='punza15@hotmail.com' AIRFLOW_CTX_DAG_OWNER='airflow' AIRFLOW_CTX_DAG_ID='bash_example' AIRFLOW_CTX_TASK_ID='test_task' AIRFLOW_CTX_EXECUTION_DATE='2024-10-21T13:52:38.529305+00:00' AIRFLOW_CTX_TRY_NUMBER='1' AIRFLOW_CTX_DAG_RUN_ID='manual__2024-10-21T13:52:38.529305+00:00'
[2024-10-21T20:54:24.451+0700] {logging_mixin.py:190} INFO - Task instance is in running state
[2024-10-21T20:54:24.452+0700] {logging_mixin.py:190} INFO -  Previous state of the Task instance: queued
[2024-10-21T20:54:24.452+0700] {logging_mixin.py:190} INFO - Current task name:test_task state:running start_date:2024-10-21 13:54:24.272095+00:00
[2024-10-21T20:54:24.453+0700] {logging_mixin.py:190} INFO - Dag name:bash_example and current dag run status:running
[2024-10-21T20:54:24.453+0700] {taskinstance.py:731} INFO - ::endgroup::
[2024-10-21T20:54:24.455+0700] {subprocess.py:63} INFO - Tmp dir root location: /var/folders/3z/w6kw66r93jxd4b5xvgpxfbkm0000gn/T
[2024-10-21T20:54:24.456+0700] {subprocess.py:75} INFO - Running command: ['/bin/bash', '-c', 'echo "2024-10-21: Test task completed" >> $(pwd)/output/test.txt']
[2024-10-21T20:54:24.466+0700] {subprocess.py:86} INFO - Output:
[2024-10-21T20:54:24.480+0700] {subprocess.py:93} INFO - /bin/bash: /private/var/folders/3z/w6kw66r93jxd4b5xvgpxfbkm0000gn/T/airflowtmpabs_hfee/output/test.txt: No such file or directory
[2024-10-21T20:54:24.481+0700] {subprocess.py:97} INFO - Command exited with return code 1
[2024-10-21T20:54:24.491+0700] {taskinstance.py:3310} ERROR - Task failed with exception
Traceback (most recent call last):
  File "/Users/punny/Documents/GitHub/NYC-Taxi-ETL-Pipeline/.venv/lib/python3.10/site-packages/airflow/models/taskinstance.py", line 767, in _execute_task
    result = _execute_callable(context=context, **execute_callable_kwargs)
  File "/Users/punny/Documents/GitHub/NYC-Taxi-ETL-Pipeline/.venv/lib/python3.10/site-packages/airflow/models/taskinstance.py", line 733, in _execute_callable
    return ExecutionCallableRunner(
  File "/Users/punny/Documents/GitHub/NYC-Taxi-ETL-Pipeline/.venv/lib/python3.10/site-packages/airflow/utils/operator_helpers.py", line 252, in run
    return self.func(*args, **kwargs)
  File "/Users/punny/Documents/GitHub/NYC-Taxi-ETL-Pipeline/.venv/lib/python3.10/site-packages/airflow/models/baseoperator.py", line 406, in wrapper
    return func(self, *args, **kwargs)
  File "/Users/punny/Documents/GitHub/NYC-Taxi-ETL-Pipeline/.venv/lib/python3.10/site-packages/airflow/operators/bash.py", line 249, in execute
    raise AirflowException(
airflow.exceptions.AirflowException: Bash command failed. The command returned a non-zero exit code 1.
[2024-10-21T20:54:24.499+0700] {logging_mixin.py:190} INFO - Task instance in failure state
[2024-10-21T20:54:24.500+0700] {logging_mixin.py:190} INFO - Task start:2024-10-21 13:54:24.272095+00:00 end:2024-10-21 13:54:24.498365+00:00 duration:0.22627
[2024-10-21T20:54:24.501+0700] {logging_mixin.py:190} INFO - Task:<Task(BashOperator): test_task> dag:<DAG: bash_example> dagrun:<DagRun bash_example @ 2024-10-21 13:52:38.529305+00:00: manual__2024-10-21T13:52:38.529305+00:00, state:running, queued_at: 2024-10-21 13:52:38.738138+00:00. externally triggered: True>
[2024-10-21T20:54:24.501+0700] {logging_mixin.py:190} INFO - Failure caused by Bash command failed. The command returned a non-zero exit code 1.
[2024-10-21T20:54:24.502+0700] {taskinstance.py:1225} INFO - Marking task as FAILED. dag_id=bash_example, task_id=test_task, run_id=manual__2024-10-21T13:52:38.529305+00:00, execution_date=20241021T135238, start_date=20241021T135424, end_date=20241021T135424
[2024-10-21T20:54:24.528+0700] {logging_mixin.py:190} WARNING - /Users/punny/Documents/GitHub/NYC-Taxi-ETL-Pipeline/.venv/lib/python3.10/site-packages/airflow/utils/email.py:155 RemovedInAirflow3Warning: Fetching SMTP credentials from configuration variables will be deprecated in a future release. Please set credentials using a connection instead.
[2024-10-21T20:54:24.529+0700] {email.py:272} INFO - Email alerting: attempt 1
[2024-10-21T20:54:31.185+0700] {email.py:272} INFO - Email alerting: attempt 1
[2024-10-21T20:54:37.974+0700] {taskinstance.py:1234} ERROR - Failed to send email to: ['punza15@hotmail.com']
Traceback (most recent call last):
  File "/Users/punny/Documents/GitHub/NYC-Taxi-ETL-Pipeline/.venv/lib/python3.10/site-packages/airflow/models/taskinstance.py", line 273, in _run_raw_task
    TaskInstance._execute_task_with_callbacks(
  File "/Users/punny/Documents/GitHub/NYC-Taxi-ETL-Pipeline/.venv/lib/python3.10/site-packages/airflow/models/taskinstance.py", line 3158, in _execute_task_with_callbacks
    result = self._execute_task(context, task_orig)
  File "/Users/punny/Documents/GitHub/NYC-Taxi-ETL-Pipeline/.venv/lib/python3.10/site-packages/airflow/models/taskinstance.py", line 3182, in _execute_task
    return _execute_task(self, context, task_orig)
  File "/Users/punny/Documents/GitHub/NYC-Taxi-ETL-Pipeline/.venv/lib/python3.10/site-packages/airflow/models/taskinstance.py", line 767, in _execute_task
    result = _execute_callable(context=context, **execute_callable_kwargs)
  File "/Users/punny/Documents/GitHub/NYC-Taxi-ETL-Pipeline/.venv/lib/python3.10/site-packages/airflow/models/taskinstance.py", line 733, in _execute_callable
    return ExecutionCallableRunner(
  File "/Users/punny/Documents/GitHub/NYC-Taxi-ETL-Pipeline/.venv/lib/python3.10/site-packages/airflow/utils/operator_helpers.py", line 252, in run
    return self.func(*args, **kwargs)
  File "/Users/punny/Documents/GitHub/NYC-Taxi-ETL-Pipeline/.venv/lib/python3.10/site-packages/airflow/models/baseoperator.py", line 406, in wrapper
    return func(self, *args, **kwargs)
  File "/Users/punny/Documents/GitHub/NYC-Taxi-ETL-Pipeline/.venv/lib/python3.10/site-packages/airflow/operators/bash.py", line 249, in execute
    raise AirflowException(
airflow.exceptions.AirflowException: Bash command failed. The command returned a non-zero exit code 1.

During handling of the above exception, another exception occurred:

Traceback (most recent call last):
  File "/Users/punny/Documents/GitHub/NYC-Taxi-ETL-Pipeline/.venv/lib/python3.10/site-packages/airflow/models/taskinstance.py", line 1442, in _email_alert
    send_email(task.email, subject, html_content)
  File "/Users/punny/Documents/GitHub/NYC-Taxi-ETL-Pipeline/.venv/lib/python3.10/site-packages/airflow/utils/email.py", line 80, in send_email
    return backend(
  File "/Users/punny/Documents/GitHub/NYC-Taxi-ETL-Pipeline/.venv/lib/python3.10/site-packages/airflow/utils/email.py", line 155, in send_email_smtp
    send_mime_email(e_from=mail_from, e_to=recipients, mime_msg=msg, conn_id=conn_id, dryrun=dryrun)
  File "/Users/punny/Documents/GitHub/NYC-Taxi-ETL-Pipeline/.venv/lib/python3.10/site-packages/airflow/utils/email.py", line 282, in send_mime_email
    smtp_conn.login(smtp_user, smtp_password)
  File "/usr/local/Cellar/python@3.10/3.10.15/Frameworks/Python.framework/Versions/3.10/lib/python3.10/smtplib.py", line 750, in login
    raise last_exception
  File "/usr/local/Cellar/python@3.10/3.10.15/Frameworks/Python.framework/Versions/3.10/lib/python3.10/smtplib.py", line 739, in login
    (code, resp) = self.auth(
  File "/usr/local/Cellar/python@3.10/3.10.15/Frameworks/Python.framework/Versions/3.10/lib/python3.10/smtplib.py", line 662, in auth
    raise SMTPAuthenticationError(code, resp)
smtplib.SMTPAuthenticationError: (535, b'5.7.139 Authentication unsuccessful, basic authentication is disabled. [KL1P15301CA0064.APCP153.PROD.OUTLOOK.COM 2024-10-21T13:54:31.188Z 08DCF1BA5454FEC7]')

During handling of the above exception, another exception occurred:

Traceback (most recent call last):
  File "/Users/punny/Documents/GitHub/NYC-Taxi-ETL-Pipeline/.venv/lib/python3.10/site-packages/airflow/models/taskinstance.py", line 1232, in _handle_failure
    task_instance.email_alert(error, failure_context["task"])
  File "/Users/punny/Documents/GitHub/NYC-Taxi-ETL-Pipeline/.venv/lib/python3.10/site-packages/airflow/models/taskinstance.py", line 3604, in email_alert
    _email_alert(task_instance=self, exception=exception, task=task)
  File "/Users/punny/Documents/GitHub/NYC-Taxi-ETL-Pipeline/.venv/lib/python3.10/site-packages/airflow/models/taskinstance.py", line 1444, in _email_alert
    send_email(task.email, subject, html_content_err)
  File "/Users/punny/Documents/GitHub/NYC-Taxi-ETL-Pipeline/.venv/lib/python3.10/site-packages/airflow/utils/email.py", line 80, in send_email
    return backend(
  File "/Users/punny/Documents/GitHub/NYC-Taxi-ETL-Pipeline/.venv/lib/python3.10/site-packages/airflow/utils/email.py", line 155, in send_email_smtp
    send_mime_email(e_from=mail_from, e_to=recipients, mime_msg=msg, conn_id=conn_id, dryrun=dryrun)
  File "/Users/punny/Documents/GitHub/NYC-Taxi-ETL-Pipeline/.venv/lib/python3.10/site-packages/airflow/utils/email.py", line 282, in send_mime_email
    smtp_conn.login(smtp_user, smtp_password)
  File "/usr/local/Cellar/python@3.10/3.10.15/Frameworks/Python.framework/Versions/3.10/lib/python3.10/smtplib.py", line 750, in login
    raise last_exception
  File "/usr/local/Cellar/python@3.10/3.10.15/Frameworks/Python.framework/Versions/3.10/lib/python3.10/smtplib.py", line 739, in login
    (code, resp) = self.auth(
  File "/usr/local/Cellar/python@3.10/3.10.15/Frameworks/Python.framework/Versions/3.10/lib/python3.10/smtplib.py", line 662, in auth
    raise SMTPAuthenticationError(code, resp)
smtplib.SMTPAuthenticationError: (535, b'5.7.139 Authentication unsuccessful, basic authentication is disabled. [KL1P15301CA0049.APCP153.PROD.OUTLOOK.COM 2024-10-21T13:54:38.061Z 08DCF1B559C9C89A]')
[2024-10-21T20:54:37.989+0700] {taskinstance.py:340} INFO - ::group::Post task execution logs
[2024-10-21T20:54:37.990+0700] {standard_task_runner.py:124} ERROR - Failed to execute job 18 for task test_task (Bash command failed. The command returned a non-zero exit code 1.; 5887)
Traceback (most recent call last):
  File "/Users/punny/Documents/GitHub/NYC-Taxi-ETL-Pipeline/.venv/lib/python3.10/site-packages/airflow/task/task_runner/standard_task_runner.py", line 117, in _start_by_fork
    ret = args.func(args, dag=self.dag)
  File "/Users/punny/Documents/GitHub/NYC-Taxi-ETL-Pipeline/.venv/lib/python3.10/site-packages/airflow/cli/cli_config.py", line 49, in command
    return func(*args, **kwargs)
  File "/Users/punny/Documents/GitHub/NYC-Taxi-ETL-Pipeline/.venv/lib/python3.10/site-packages/airflow/utils/cli.py", line 115, in wrapper
    return f(*args, **kwargs)
  File "/Users/punny/Documents/GitHub/NYC-Taxi-ETL-Pipeline/.venv/lib/python3.10/site-packages/airflow/cli/commands/task_command.py", line 483, in task_run
    task_return_code = _run_task_by_selected_method(args, _dag, ti)
  File "/Users/punny/Documents/GitHub/NYC-Taxi-ETL-Pipeline/.venv/lib/python3.10/site-packages/airflow/cli/commands/task_command.py", line 256, in _run_task_by_selected_method
    return _run_raw_task(args, ti)
  File "/Users/punny/Documents/GitHub/NYC-Taxi-ETL-Pipeline/.venv/lib/python3.10/site-packages/airflow/cli/commands/task_command.py", line 341, in _run_raw_task
    return ti._run_raw_task(
  File "/Users/punny/Documents/GitHub/NYC-Taxi-ETL-Pipeline/.venv/lib/python3.10/site-packages/airflow/utils/session.py", line 97, in wrapper
    return func(*args, session=session, **kwargs)
  File "/Users/punny/Documents/GitHub/NYC-Taxi-ETL-Pipeline/.venv/lib/python3.10/site-packages/airflow/models/taskinstance.py", line 3004, in _run_raw_task
    return _run_raw_task(
  File "/Users/punny/Documents/GitHub/NYC-Taxi-ETL-Pipeline/.venv/lib/python3.10/site-packages/airflow/models/taskinstance.py", line 273, in _run_raw_task
    TaskInstance._execute_task_with_callbacks(
  File "/Users/punny/Documents/GitHub/NYC-Taxi-ETL-Pipeline/.venv/lib/python3.10/site-packages/airflow/models/taskinstance.py", line 3158, in _execute_task_with_callbacks
    result = self._execute_task(context, task_orig)
  File "/Users/punny/Documents/GitHub/NYC-Taxi-ETL-Pipeline/.venv/lib/python3.10/site-packages/airflow/models/taskinstance.py", line 3182, in _execute_task
    return _execute_task(self, context, task_orig)
  File "/Users/punny/Documents/GitHub/NYC-Taxi-ETL-Pipeline/.venv/lib/python3.10/site-packages/airflow/models/taskinstance.py", line 767, in _execute_task
    result = _execute_callable(context=context, **execute_callable_kwargs)
  File "/Users/punny/Documents/GitHub/NYC-Taxi-ETL-Pipeline/.venv/lib/python3.10/site-packages/airflow/models/taskinstance.py", line 733, in _execute_callable
    return ExecutionCallableRunner(
  File "/Users/punny/Documents/GitHub/NYC-Taxi-ETL-Pipeline/.venv/lib/python3.10/site-packages/airflow/utils/operator_helpers.py", line 252, in run
    return self.func(*args, **kwargs)
  File "/Users/punny/Documents/GitHub/NYC-Taxi-ETL-Pipeline/.venv/lib/python3.10/site-packages/airflow/models/baseoperator.py", line 406, in wrapper
    return func(self, *args, **kwargs)
  File "/Users/punny/Documents/GitHub/NYC-Taxi-ETL-Pipeline/.venv/lib/python3.10/site-packages/airflow/operators/bash.py", line 249, in execute
    raise AirflowException(
airflow.exceptions.AirflowException: Bash command failed. The command returned a non-zero exit code 1.
[2024-10-21T20:54:38.031+0700] {local_task_job_runner.py:266} INFO - Task exited with return code 1
[2024-10-21T20:54:38.054+0700] {taskinstance.py:3900} INFO - 0 downstream tasks scheduled from follow-on schedule check
[2024-10-21T20:54:38.060+0700] {local_task_job_runner.py:245} INFO - ::endgroup::
